server/tests/fixtures/hl_dual_validator/golden/parser_tob_end_of_block_quotes.jsonl
{"channel":"marketdata","channel_id":0,"fields":{"ask_n":49,"ask_price":81308,"ask_px_raw":813080,"ask_qty":6.08207,"ask_source_count":49,"ask_sz_raw":608207000,"bid_n":4,"bid_price":81307,"bid_px_raw":813070,"bid_qty":0.20195,"bid_source_count":4,"bid_sz_raw":20195000,"price_exponent":-1,"qty_exponent":-8,"send_timestamp_ns":0,"snapshot":false,"source_id":1,"source_ts_ms":0,"source_ts_ns":0,"update_flags":3},"reset_count":0,"seq":0,"symbol":"BTC","ts":"1970-01-01T00:00:00Z","type":"quote"}
{"channel":"marketdata","channel_id":0,"fields":{"ask_n":49,"ask_price":81308,"ask_px_raw":813080,"ask_qty":6.08174,"ask_source_count":49,"ask_sz_raw":608174000,"bid_n":4,"bid_price":81307,"bid_px_raw":813070,"bid_qty":0.20195,"bid_source_count":4,"bid_sz_raw":20195000,"price_exponent":-1,"qty_exponent":-8,"send_timestamp_ns":0,"snapshot":false,"source_id":1,"source_ts_ms":1778002753024,"source_ts_ns":1778002753024000000,"update_flags":3},"reset_count":0,"seq":0,"symbol":"BTC","ts":"2026-05-05T17:39:13.024Z","type":"quote"}
{"channel":"marketdata","channel_id":0,"fields":{"ask_n":50,"ask_price":81308,"ask_px_raw":813080,"ask_qty":6.69664,"ask_source_count":50,"ask_sz_raw":669664000,"bid_n":4,"bid_price":81307,"bid_px_raw":813070,"bid_qty":0.20195,"bid_source_count":4,"bid_sz_raw":20195000,"price_exponent":-1,"qty_exponent":-8,"send_timestamp_ns":0,"snapshot":false,"source_id":1,"source_ts_ms":1778002753098,"source_ts_ns":1778002753098000000,"update_flags":3},"reset_count":0,"seq":0,"symbol":"BTC","ts":"2026-05-05T17:39:13.098Z","type":"quote"}
{"channel":"marketdata","channel_id":0,"fields":{"ask_n":52,"ask_price":81308,"ask_px_raw":813080,"ask_qty":7.451350000000001,"ask_source_count":52,"ask_sz_raw":745135000,"bid_n":4,"bid_price":81307,"bid_px_raw":813070,"bid_qty":0.20195,"bid_source_count":4,"bid_sz_raw":20195000,"price_exponent":-1,"qty_exponent":-8,"send_timestamp_ns":0,"snapshot":false,"source_id":1,"source_ts_ms":1778002753167,"source_ts_ns":1778002753167000000,"update_flags":3},"reset_count":0,"seq":0,"symbol":"BTC","ts":"2026-05-05T17:39:13.167Z","type":"quote"}
{"channel":"marketdata","channel_id":0,"fields":{"ask_n":51,"ask_price":81308,"ask_px_raw":813080,"ask_qty":6.83645,"ask_source_count":51,"ask_sz_raw":683645000,"bid_n":4,"bid_price":81307,"bid_px_raw":813070,"bid_qty":0.20195,"bid_source_count":4,"bid_sz_raw":20195000,"price_exponent":-1,"qty_exponent":-8,"send_timestamp_ns":0,"snapshot":false,"source_id":1,"source_ts_ms":1778002753236,"source_ts_ns":1778002753236000000,"update_flags":3},"reset_count":0,"seq":0,"symbol":"BTC","ts":"2026-05-05T17:39:13.236Z","type":"quote"}
{"channel":"marketdata","channel_id":0,"fields":{"ask_n":54,"ask_price":81308,"ask_px_raw":813080,"ask_qty":7.64323,"ask_source_count":54,"ask_sz_raw":764323000,"bid_n":3,"bid_price":81307,"bid_px_raw":813070,"bid_qty":0.0181,"bid_source_count":3,"bid_sz_raw":1810000,"price_exponent":-1,"qty_exponent":-8,"send_timestamp_ns":0,"snapshot":false,"source_id":1,"source_ts_ms":1778002753300,"source_ts_ns":1778002753300000000,"update_flags":3},"reset_count":0,"seq":0,"symbol":"BTC","ts":"2026-05-05T17:39:13.3Z","type":"quote"}
{"channel":"marketdata","channel_id":0,"fields":{"ask_n":55,"ask_price":81308,"ask_px_raw":813080,"ask_qty":8.56558,"ask_source_count":55,"ask_sz_raw":856558000,"bid_n":3,"bid_price":81307,"bid_px_raw":813070,"bid_qty":0.0181,"bid_source_count":3,"bid_sz_raw":1810000,"price_exponent":-1,"qty_exponent":-8,"send_timestamp_ns":0,"snapshot":false,"source_id":1,"source_ts_ms":1778002753372,"source_ts_ns":1778002753372000000,"update_flags":3},"reset_count":0,"seq":0,"symbol":"BTC","ts":"2026-05-05T17:39:13.372Z","type":"quote"}
{"channel":"marketdata","channel_id":0,"fields":{"ask_n":59,"ask_price":81308,"ask_px_raw":813080,"ask_qty":10.90514,"ask_source_count":59,"ask_sz_raw":1090514000,"bid_n":3,"bid_price":81307,"bid_px_raw":813070,"bid_qty":0.0181,"bid_source_count":3,"bid_sz_raw":1810000,"price_exponent":-1,"qty_exponent":-8,"send_timestamp_ns":0,"snapshot":false,"source_id":1,"source_ts_ms":1778002753445,"source_ts_ns":1778002753445000000,"update_flags":3},"reset_count":0,"seq":0,"symbol":"BTC","ts":"2026-05-05T17:39:13.445Z","type":"quote"}
{"channel":"marketdata","channel_id":0,"fields":{"ask_n":54,"ask_price":81308,"ask_px_raw":813080,"ask_qty":6.63879,"ask_source_count":54,"ask_sz_raw":663879000,"bid_n":4,"bid_price":81307,"bid_px_raw":813070,"bid_qty":1.70246,"bid_source_count":4,"bid_sz_raw":170246000,"price_exponent":-1,"qty_exponent":-8,"send_timestamp_ns":0,"snapshot":false,"source_id":1,"source_ts_ms":1778002753505,"source_ts_ns":1778002753505000000,"update_flags":3},"reset_count":0,"seq":0,"symbol":"BTC","ts":"2026-05-05T17:39:13.505Z","type":"quote"}
{"channel":"marketdata","channel_id":0,"fields":{"ask_n":55,"ask_price":81308,"ask_px_raw":813080,"ask_qty":6.72879,"ask_source_count":55,"ask_sz_raw":672879000,"bid_n":5,"bid_price":81307,"bid_px_raw":813070,"bid_qty":2.31735,"bid_source_count":5,"bid_sz_raw":231735000,"price_exponent":-1,"qty_exponent":-8,"send_timestamp_ns":0,"snapshot":false,"source_id":1,"source_ts_ms":1778002753569,"source_ts_ns":1778002753569000000,"update_flags":3},"reset_count":0,"seq":0,"symbol":"BTC","ts":"2026-05-05T17:39:13.569Z","type":"quote"}
{"channel":"marketdata","channel_id":0,"fields":{"ask_n":57,"ask_price":81308,"ask_px_raw":813080,"ask_qty":7.13427,"ask_source_count":57,"ask_sz_raw":713427000,"bid_n":7,"bid_price":81307,"bid_px_raw":813070,"bid_qty":1.93124,"bid_source_count":7,"bid_sz_raw":193124000,"price_exponent":-1,"qty_exponent":-8,"send_timestamp_ns":0,"snapshot":false,"source_id":1,"source_ts_ms":1778002753646,"source_ts_ns":1778002753646000000,"update_flags":3},"reset_count":0,"seq":0,"symbol":"BTC","ts":"2026-05-05T17:39:13.646Z","type":"quote"}
{"channel":"marketdata","channel_id":0,"fields":{"ask_n":59,"ask_price":81308,"ask_px_raw":813080,"ask_qty":7.33427,"ask_source_count":59,"ask_sz_raw":733427000,"bid_n":5,"bid_price":81307,"bid_px_raw":813070,"bid_qty":2.57946,"bid_source_count":5,"bid_sz_raw":257946000,"price_exponent":-1,"qty_exponent":-8,"send_timestamp_ns":0,"snapshot":false,"source_id":1,"source_ts_ms":1778002753701,"source_ts_ns":1778002753701000000,"update_flags":3},"reset_count":0,"seq":0,"symbol":"BTC","ts":"2026-05-05T17:39:13.701Z","type":"quote"}
{"channel":"marketdata","channel_id":0,"fields":{"ask_n":59,"ask_price":81308,"ask_px_raw":813080,"ask_qty":7.369870000000001,"ask_source_count":59,"ask_sz_raw":736987000,"bid_n":8,"bid_price":81307,"bid_px_raw":813070,"bid_qty":3.36457,"bid_source_count":8,"bid_sz_raw":336457000,"price_exponent":-1,"qty_exponent":-8,"send_timestamp_ns":0,"snapshot":false,"source_id":1,"source_ts_ms":1778002753840,"source_ts_ns":1778002753840000000,"update_flags":3},"reset_count":0,"seq":0,"symbol":"BTC","ts":"2026-05-05T17:39:13.84Z","type":"quote"}
{"channel":"marketdata","channel_id":0,"fields":{"ask_n":58,"ask_price":81308,"ask_px_raw":813080,"ask_qty":7.27087,"ask_source_count":58,"ask_sz_raw":727087000,"bid_n":8,"bid_price":81307,"bid_px_raw":813070,"bid_qty":3.36444,"bid_source_count":8,"bid_sz_raw":336444000,"price_exponent":-1,"qty_exponent":-8,"send_timestamp_ns":0,"snapshot":false,"source_id":1,"source_ts_ms":1778002753907,"source_ts_ns":1778002753907000000,"update_flags":3},"reset_count":0,"seq":0,"symbol":"BTC","ts":"2026-05-05T17:39:13.907Z","type":"quote"}
{"channel":"marketdata","channel_id":0,"fields":{"ask_n":57,"ask_price":81308,"ask_px_raw":813080,"ask_qty":7.1808700000000005,"ask_source_count":57,"ask_sz_raw":718087000,"bid_n":12,"bid_price":81307,"bid_px_raw":813070,"bid_qty":3.95073,"bid_source_count":12,"bid_sz_raw":395073000,"price_exponent":-1,"qty_exponent":-8,"send_timestamp_ns":0,"snapshot":false,"source_id":1,"source_ts_ms":1778002753979,"source_ts_ns":1778002753979000000,"update_flags":3},"reset_count":0,"seq":0,"symbol":"BTC","ts":"2026-05-05T17:39:13.979Z","type":"quote"}
{"channel":"marketdata","channel_id":0,"fields":{"ask_n":56,"ask_price":81308,"ask_px_raw":813080,"ask_qty":6.91526,"ask_source_count":56,"ask_sz_raw":691526000,"bid_n":19,"bid_price":81307,"bid_px_raw":813070,"bid_qty":4.48583,"bid_source_count":19,"bid_sz_raw":448583000,"price_exponent":-1,"qty_exponent":-8,"send_timestamp_ns":0,"snapshot":false,"source_id":1,"source_ts_ms":1778002754041,"source_ts_ns":1778002754041000000,"update_flags":3},"reset_count":0,"seq":0,"symbol":"BTC","ts":"2026-05-05T17:39:14.041Z","type":"quote"}
